Workbook

Sheet README
A1: VELOOP REWARDS - Task 01 | Work Package F: Production Event Tracking Plan
A2: Every event is Proposed or To Be Verified. No event is claimed to exist in VELOOP today; Implementation Status is 'To be confirmed by Engineering' for all. No simulated or real VELOOP statistics are included.
A3: Naming standard: object_action in snake_case, past tense (see Naming_Standard). Common properties on every event are in Common_Envelope.
A4: KPI Dependency lists the KPIs from the KPI Catalogue (Work Package I) that use each event; it is derived from the catalogue's Required Events column.
A6: Open questions:
A7: - Which of these events are emitted today, and by which component? (A001, A011)
A8: - For each event, is the frontend or backend the right emitter? Rule proposed: interactions from the frontend, outcomes from the backend.
A9: - What idempotency design prevents a retried request from producing two events? (A005)
A10: - Is task_viewed volume acceptable, or should it be sampled?
A11: - Do features outside earning need feature_opened, or do they have their own events?
A12: - Which statuses, units, methods and categories form the approved lists used in validation? (A002, A006)
A14: Live counts
A15: Events in catalogue | B15: =COUNTA(Event_Catalogue!A:A)-1 -> 42
A16: Critical events | B16: =COUNTIF(Event_Catalogue!Q:Q,"Critical") -> 9
A17: Events To Be Verified | B17: =COUNTIF(Event_Catalogue!H:H,"To Be Verified") -> 19
A18: Brief events missing from catalogue | B18: =COUNTIF(Brief_Coverage!B:B,"No") -> 0

Sheet Event_Catalogue
A1: Event Name | B1: Trigger | C1: Definition | D1: User ID | E1: Event ID | F1: Timestamp | G1: Feature | H1: Status | I1: Required Properties | J1: Optional Properties | K1: Data Type | L1: Validation | M1: Source | N1: Business Purpose | O1: KPI Dependency | P1: Implementation Status | Q1: Priority
A2: user_registered | B2: Account creation succeeds | C2: A new user account has been created | D2: Required: user_id | E2: Required: event_id (unique) | F2: Required: event_timestamp (UTC) | G2: Account | H2: To Be Verified | I2: registration_source | J2: registration_method, referral_code_used, campaign_id, country_code | K2: registration_source: enum; registration_method: enum; referral_code_used: string; campaign_id: string; country_code: string | L2: registration_source in approved list; exactly one event per user_id; timestamp not in future | M2: Backend | N2: Start of lifecycle; acquisition analysis | O2: Registrations; Cohort Retention (Day N) | P2: To be confirmed by Engineering | Q2: Critical
A3: user_logged_in | B3: Login succeeds | C3: A user has started an authenticated visit | D3: Required: user_id | E3: Required: event_id (unique) | F3: Required: event_timestamp (UTC) | G3: Account | H3: Proposed | J3: attempt_number | K3: attempt_number: integer | L3: user_id must exist; timestamp not before registration | M3: Backend | N3: Return behaviour; visit counts (kept separate from 'active') | O3: Daily Visitors | P3: To be confirmed by Engineering | Q3: High
A4: user_logged_out | B4: User chooses logout (where logout exists) | C4: A user has ended a visit by logging out | D4: Required: user_id | E4: Required: event_id (unique) | F4: Required: event_timestamp (UTC) | G4: Account | H4: Proposed | L4: Not before a prior user_logged_in; may be absent for timeouts | M4: Frontend | N4: Session length where applicable | O4: No dedicated KPI yet (kept for lineage and definitions) | P4: To be confirmed by Engineering | Q4: Low
A5: onboarding_started | B5: First onboarding screen shown | C5: User has entered the onboarding flow | D5: Required: user_id | E5: Required: event_id (unique) | F5: Required: event_timestamp (UTC) | G5: Account | H5: Proposed | I5: onboarding_step | K5: onboarding_step: string | L5: onboarding_step in current flow list; once per user unless flow restarts | M5: Frontend | N5: Onboarding funnel entry | O5: Onboarding Completion Rate | P5: To be confirmed by Engineering | Q5: High
A6: onboarding_completed | B6: Final onboarding step done | C6: User has finished onboarding | D6: Required: user_id | E6: Required: event_id (unique) | F6: Required: event_timestamp (UTC) | G6: Account | H6: Proposed | I6: onboarding_step | J6: step_completed_count | K6: onboarding_step: string; step_completed_count: integer | L6: Must follow onboarding_started; once per user | M6: Backend | N6: Activation proxy | O6: Onboarding Completion Rate | P6: To be confirmed by Engineering | Q6: High
A7: account_status_changed | B7: account_status updated by user, system or operations | C7: An account moved from one status to another | D7: Required: user_id | E7: Required: event_id (unique) | F7: Required: event_timestamp (UTC) | G7: Account | H7: To Be Verified | I7: previous_status, new_status, status_change_actor | J7: reason_category | K7: previous_status: enum; new_status: enum; status_change_actor: enum; reason_category: enum | L7: previous_status differs from new_status; values in approved status list | M7: Backend | N7: Track restrictions and closures | O7: Account Status Mix | P7: To be confirmed by Engineering | Q7: High
A8: task_viewed | B8: Task card visible on screen | C8: A task was shown to the user | D8: Required: user_id | E8: Required: event_id (unique) | F8: Required: event_timestamp (UTC) | G8: Tasks | H8: Proposed | I8: task_id, task_type, feature | J8: screen_name | K8: task_id: string; task_type: enum; feature: enum; screen_name: string | L8: Only when visible, not when merely loaded; sample if volume is high | M8: Frontend | N8: Discovery-to-start funnel | O8: Task Open Rate | P8: To be confirmed by Engineering | Q8: Medium
A9: task_opened | B9: User opens task detail | C9: User opened a task | D9: Required: user_id | E9: Required: event_id (unique) | F9: Required: event_timestamp (UTC) | G9: Tasks | H9: Proposed | I9: task_id, task_type, feature | K9: task_id: string; task_type: enum; feature: enum | L9: task_id exists in catalogue | M9: Frontend | N9: Intent measurement | O9: Task Open Rate | P9: To be confirmed by Engineering | Q9: Medium
A10: task_started | B10: Task attempt record created | C10: User began an attempt at a task | D10: Required: user_id | E10: Required: event_id (unique) | F10: Required: event_timestamp (UTC) | G10: Tasks | H10: Proposed | I10: task_activity_id, task_id, task_type, feature | J10: provider_name, provider_reference_id, attempt_number | K10: task_activity_id: string; task_id: string; task_type: enum; feature: enum; provider_name: string; provider_reference_id: string; attempt_number: integer | L10: task_activity_id unique; task_id exists; one event per attempt | M10: Backend | N10: Denominator for completion rate | O10: Feature Usage; Feature Adoption Rate; Task Starts; Task Completion Rate; Repeat Usage Rate; Provider Callback Reliability | P10: To be confirmed by Engineering | Q10: Critical
A11: task_completed | B11: Completion has passed the applicable validation | C11: A task attempt was validated as completed | D11: Required: user_id | E11: Required: event_id (unique) | F11: Required: event_timestamp (UTC) | G11: Tasks | H11: Proposed | I11: task_activity_id, task_id, task_type, reward_amount, reward_unit, validation_status | J11: reward_id, provider_reference_id | K11: task_activity_id: string; task_id: string; task_type: enum; reward_amount: decimal; reward_unit: enum; validation_status: enum; reward_id: string; provider_reference_id: string | L11: validation_status = passed; exactly one per task_activity_id; reward_unit in approved list; reward_amount not negative | M11: Backend | N11: Counts real completions only | O11: Daily Active Users (DAU); Weekly Active Users (WAU); Monthly Active Users (MAU); Returning Users; Cohort Retention (Day N); Feature Adoption Rate; Task Completions; Task Completion Rate; Help-Center Engagement | P11: To be confirmed by Engineering | Q11: Critical
A12: task_failed | B12: Attempt ends without validated completion | C12: A task attempt failed or was abandoned | D12: Required: user_id | E12: Required: event_id (unique) | F12: Required: event_timestamp (UTC) | G12: Tasks | H12: Proposed | I12: task_activity_id, task_id, failure_category | J12: failure_detail_code, provider_name, provider_reference_id | K12: task_activity_id: string; task_id: string; failure_category: enum; failure_detail_code: string; provider_name: string; provider_reference_id: string | L12: failure_category in approved list; cannot follow task_completed for the same attempt | M12: Backend | N12: Explain drop-off and failures | O12: Task Failure Mix | P12: To be confirmed by Engineering | Q12: High
A13: reward_pending | B13: Reward created but not yet usable | C13: A reward is held awaiting validation or confirmation | D13: Required: user_id | E13: Required: event_id (unique) | F13: Required: event_timestamp (UTC) | G13: Rewards | H13: Proposed | I13: reward_id, reward_amount, reward_unit, source_feature, pending_reason | J13: task_activity_id | K13: reward_id: string; reward_amount: decimal; reward_unit: enum; source_feature: enum; pending_reason: enum; task_activity_id: string | L13: reward_id unique; reward_amount greater than 0 | M13: Backend | N13: Pending reward queue | O13: Reward Transactions; Pending Rewards | P13: To be confirmed by Engineering | Q13: High
A14: reward_credited | B14: Wallet balance updated with the reward | C14: A reward has actually been added to the wallet | D14: Required: user_id | E14: Required: event_id (unique) | F14: Required: event_timestamp (UTC) | G14: Rewards | H14: Proposed | I14: reward_id, reward_amount, reward_unit, source_feature, wallet_transaction_id | J14: task_activity_id | K14: reward_id: string; reward_amount: decimal; reward_unit: enum; source_feature: enum; wallet_transaction_id: string; task_activity_id: string | L14: Exactly one per reward_id; wallet_transaction_id must exist; amount greater than 0 | M14: Backend | N14: Counts rewards actually given | O14: Reward Transactions; Reward Credits; Reward Reversal Rate; Reward Activity by Feature; Pending Rewards; Net Reward Amount | P14: To be confirmed by Engineering | Q14: Critical
A15: reward_reversed | B15: A credited reward is taken back | C15: A previously credited reward was reversed | D15: Required: user_id | E15: Required: event_id (unique) | F15: Required: event_timestamp (UTC) | G15: Rewards | H15: Proposed | I15: reward_id, original_reward_id, reward_amount, reward_unit, reason_category, wallet_transaction_id | K15: reward_id: string; original_reward_id: string; reward_amount: decimal; reward_unit: enum; reason_category: enum; wallet_transaction_id: string | L15: original_reward_id must refer to a credited reward; no second reversal of the same reward | M15: Backend | N15: Reward reliability | O15: Reward Transactions; Reward Reversals; Reward Reversal Rate; Net Reward Amount | P15: To be confirmed by Engineering | Q15: Critical
A16: reward_corrected | B16: Reward amount changed after crediting | C16: A credited reward amount was corrected | D16: Required: user_id | E16: Required: event_id (unique) | F16: Required: event_timestamp (UTC) | G16: Rewards | H16: Proposed | I16: reward_id, old_amount, new_amount, reward_unit, correction_reason | J16: wallet_transaction_id | K16: reward_id: string; old_amount: decimal; new_amount: decimal; reward_unit: enum; correction_reason: enum; wallet_transaction_id: string | L16: old_amount differs from new_amount; reward must exist | M16: Backend | N16: Detect after-the-fact changes | O16: Reward Transactions; Net Reward Amount | P16: To be confirmed by Engineering | Q16: Medium
A17: reward_rejected | B17: Pending reward will never be credited (if this state exists) | C17: A pending reward was refused or expired | D17: Required: user_id | E17: Required: event_id (unique) | F17: Required: event_timestamp (UTC) | G17: Rewards | H17: To Be Verified | I17: reward_id, reason_category | K17: reward_id: string; reason_category: enum | L17: Must follow reward_pending; cannot follow reward_credited | M17: Backend | N17: Pending reward outcomes | O17: Pending Rewards | P17: To be confirmed by Engineering | Q17: Medium
A18: daily_reward_claimed | B18: Daily reward successfully claimed | C18: User claimed the daily reward | D18: Required: user_id | E18: Required: event_id (unique) | F18: Required: event_timestamp (UTC) | G18: Daily & Engagement | H18: Proposed | I18: claim_date, streak_day, reward_amount, reward_unit | J18: reward_id | K18: claim_date: date; streak_day: integer; reward_amount: decimal; reward_unit: enum; reward_id: string | L18: One per user per claim_date; reward_amount not negative | M18: Backend | N18: Daily habit measurement | O18: Daily Active Users (DAU); Weekly Active Users (WAU); Monthly Active Users (MAU); Returning Users; Cohort Retention (Day N); Feature Adoption Rate; Streak Length; Help-Center Engagement | P18: To be confirmed by Engineering | Q18: High
A19: streak_updated | B19: Streak incremented or reset | C19: A user's streak changed | D19: Required: user_id | E19: Required: event_id (unique) | F19: Required: event_timestamp (UTC) | G19: Daily & Engagement | H19: Proposed | I19: streak_count, previous_streak_count, change_type | K19: streak_count: integer; previous_streak_count: integer; change_type: enum | L19: change_type in (increment, reset); counts consistent with change_type | M19: Backend | N19: Streak length and breaks | O19: Streak Length | P19: To be confirmed by Engineering | Q19: Medium
A20: mission_started | B20: Mission attempt begins | C20: User started a mission | D20: Required: user_id | E20: Required: event_id (unique) | F20: Required: event_timestamp (UTC) | G20: Daily & Engagement | H20: Proposed | I20: mission_id, mission_type | K20: mission_id: string; mission_type: enum | L20: mission_id exists | M20: Backend | N20: Mission funnel start | O20: Feature Usage; Feature Adoption Rate; Repeat Usage Rate; Mission Completion Rate | P20: To be confirmed by Engineering | Q20: Medium
A21: mission_completed | B21: System marks mission complete | C21: A mission was completed | D21: Required: user_id | E21: Required: event_id (unique) | F21: Required: event_timestamp (UTC) | G21: Daily & Engagement | H21: Proposed | I21: mission_id, mission_type | J21: reward_amount, reward_unit, progress_value | K21: mission_id: string; mission_type: enum; reward_amount: decimal; reward_unit: enum; progress_value: decimal | L21: Must follow mission_started; once per mission attempt | M21: Backend | N21: Mission outcomes | O21: Daily Active Users (DAU); Weekly Active Users (WAU); Monthly Active Users (MAU); Returning Users; Cohort Retention (Day N); Feature Adoption Rate; Mission Completion Rate; Help-Center Engagement | P21: To be confirmed by Engineering | Q21: Medium
A22: badge_earned | B22: Badge awarded | C22: User earned a badge | D22: Required: user_id | E22: Required: event_id (unique) | F22: Required: event_timestamp (UTC) | G22: Daily & Engagement | H22: Proposed | I22: badge_id | K22: badge_id: string | L22: One per user per badge_id | M22: Backend | N22: Progression effects | O22: No dedicated KPI yet (kept for lineage and definitions) | P22: To be confirmed by Engineering | Q22: Low
A23: spin_started | B23: User starts a spin | C23: User started a spin | D23: Required: user_id | E23: Required: event_id (unique) | F23: Required: event_timestamp (UTC) | G23: Daily & Engagement | H23: Proposed | I23: spin_id | K23: spin_id: string | L23: spin_id unique | M23: Frontend | N23: Feature adoption | O23: Feature Usage; Feature Adoption Rate; Repeat Usage Rate | P23: To be confirmed by Engineering | Q23: Medium
A24: spin_completed | B24: Spin outcome decided | C24: A spin ended with an outcome | D24: Required: user_id | E24: Required: event_id (unique) | F24: Required: event_timestamp (UTC) | G24: Daily & Engagement | H24: Proposed | I24: spin_id, outcome_category | J24: reward_amount, reward_unit | K24: spin_id: string; outcome_category: enum; reward_amount: decimal; reward_unit: enum | L24: Must follow spin_started; one per spin_id | M24: Backend | N24: Payout distribution | O24: Daily Active Users (DAU); Weekly Active Users (WAU); Monthly Active Users (MAU); Returning Users; Cohort Retention (Day N); Feature Adoption Rate; Help-Center Engagement | P24: To be confirmed by Engineering | Q24: Medium
A25: mining_started | B25: Mining cycle begins | C25: User started a mining cycle | D25: Required: user_id | E25: Required: event_id (unique) | F25: Required: event_timestamp (UTC) | G25: Daily & Engagement | H25: To Be Verified | I25: mining_cycle_id | K25: mining_cycle_id: string | L25: mining_cycle_id unique | M25: Backend | N25: Start of return loop | O25: Feature Usage; Feature Adoption Rate; Repeat Usage Rate | P25: To be confirmed by Engineering | Q25: Medium
A26: mining_claimed | B26: User claims mining result | C26: User claimed a completed mining cycle | D26: Required: user_id | E26: Required: event_id (unique) | F26: Required: event_timestamp (UTC) | G26: Daily & Engagement | H26: To Be Verified | I26: mining_cycle_id, reward_amount, reward_unit | J26: reward_id | K26: mining_cycle_id: string; reward_amount: decimal; reward_unit: enum; reward_id: string | L26: Must follow mining_started; once per cycle | M26: Backend | N26: Return behaviour | O26: Daily Active Users (DAU); Weekly Active Users (WAU); Monthly Active Users (MAU); Returning Users; Cohort Retention (Day N); Feature Adoption Rate; Help-Center Engagement | P26: To be confirmed by Engineering | Q26: Medium
A27: feature_opened | B27: User opens a feature screen (name to be agreed) | C27: User opened a product feature | D27: Required: user_id | E27: Required: event_id (unique) | F27: Required: event_timestamp (UTC) | G27: Daily & Engagement | H27: To Be Verified | I27: feature_name | J27: screen_name | K27: feature_name: enum; screen_name: string | L27: feature_name in approved list; used only for features without their own start event | M27: Frontend | N27: Adoption of non-earning features | O27: Feature Usage; Feature Adoption Rate; Help-Center Engagement | P27: To be confirmed by Engineering | Q27: Medium
A28: referral_created | B28: Referral code or link created | C28: A referral was created by a user | D28: Required: user_id | E28: Required: event_id (unique) | F28: Required: event_timestamp (UTC) | G28: Referrals | H28: Proposed | I28: referral_id, referring_user_id | J28: referral_code_used, campaign_id | K28: referral_id: string; referring_user_id: string; referral_code_used: string; campaign_id: string | L28: referral_id unique; referring_user_id must exist | M28: Backend | N28: Referral funnel start | O28: Referrals Created; Referral Conversion Rate | P28: To be confirmed by Engineering | Q28: High
A29: referral_registered | B29: Referred user completes sign-up | C29: A referred user registered | D29: Required: user_id | E29: Required: event_id (unique) | F29: Required: event_timestamp (UTC) | G29: Referrals | H29: Proposed | I29: referral_id, referring_user_id, referred_user_id | K29: referral_id: string; referring_user_id: string; referred_user_id: string | L29: referred_user_id differs from referring_user_id; follows referral_created | M29: Backend | N29: Registration is not conversion | O29: Referral Registrations; Referral Activation Rate | P29: To be confirmed by Engineering | Q29: High
A30: referral_activated | B30: Referred user meets activation rule | C30: A referred user became activated | D30: Required: user_id | E30: Required: event_id (unique) | F30: Required: event_timestamp (UTC) | G30: Referrals | H30: To Be Verified | I30: referral_id, referred_user_id, activation_rule_version | K30: referral_id: string; referred_user_id: string; activation_rule_version: string | L30: Follows referral_registered; once per referral_id | M30: Backend | N30: Quality of referrals | O30: Referral Activations; Referral Activation Rate | P30: To be confirmed by Engineering | Q30: High
A31: referral_converted | B31: Referral meets success condition | C31: A referral was successful | D31: Required: user_id | E31: Required: event_id (unique) | F31: Required: event_timestamp (UTC) | G31: Referrals | H31: Proposed | I31: referral_id, referring_user_id, referred_user_id | J31: reward_id, wallet_transaction_id | K31: referral_id: string; referring_user_id: string; referred_user_id: string; reward_id: string; wallet_transaction_id: string | L31: Follows referral_activated unless rule says otherwise; once per referral_id | M31: Backend | N31: True referral success | O31: Referral Conversions; Referral Conversion Rate | P31: To be confirmed by Engineering | Q31: High
A32: wallet_transaction_created | B32: Ledger entry created | C32: A wallet entry was created | D32: Required: user_id | E32: Required: event_id (unique) | F32: Required: event_timestamp (UTC) | G32: Wallet | H32: To Be Verified | I32: wallet_transaction_id, transaction_type, direction, amount, unit, reference_id, source_feature | J32: related_transaction_id, exchange_group_id | K32: wallet_transaction_id: string; transaction_type: enum; direction: enum; amount: decimal; unit: enum; reference_id: string; source_feature: enum; related_transaction_id: string; exchange_group_id: string | L32: wallet_transaction_id unique; amount greater than 0; direction agrees with transaction_type | M32: Backend | N32: Every balance change has a record | O32: Wallet Transactions | P32: To be confirmed by Engineering | Q32: Critical
A33: wallet_transaction_completed | B33: Ledger entry becomes final | C33: A wallet entry was completed | D33: Required: user_id | E33: Required: event_id (unique) | F33: Required: event_timestamp (UTC) | G33: Wallet | H33: To Be Verified | I33: wallet_transaction_id, transaction_type, direction, amount, unit, transaction_status | K33: wallet_transaction_id: string; transaction_type: enum; direction: enum; amount: decimal; unit: enum; transaction_status: enum | L33: Follows wallet_transaction_created; once per transaction | M33: Backend | N33: Settlement and balance integrity | O33: Wallet Transactions; Credit Volume; Redemption Activity; Wallet Reconciliation Exceptions | P33: To be confirmed by Engineering | Q33: High
A34: wallet_transaction_reversed | B34: Reversal entry created | C34: An earlier wallet entry was reversed | D34: Required: user_id | E34: Required: event_id (unique) | F34: Required: event_timestamp (UTC) | G34: Wallet | H34: To Be Verified | I34: wallet_transaction_id, related_transaction_id, amount, unit, reason_category | K34: wallet_transaction_id: string; related_transaction_id: string; amount: decimal; unit: enum; reason_category: enum | L34: related_transaction_id exists and is not itself a reversal | M34: Backend | N34: Reversal tracking | O34: Wallet Reversals | P34: To be confirmed by Engineering | Q34: Critical
A35: wallet_exchange_completed | B35: Exchange of units finalised | C35: A unit exchange finished | D35: Required: user_id | E35: Required: event_id (unique) | F35: Required: event_timestamp (UTC) | G35: Wallet | H35: To Be Verified | I35: exchange_group_id, from_unit, to_unit, from_amount, to_amount | J35: exchange_rate_applied | K35: exchange_group_id: string; from_unit: enum; to_unit: enum; from_amount: decimal; to_amount: decimal; exchange_rate_applied: decimal | L35: One debit and one credit per exchange_group_id | M35: Backend | N35: Exchange activity | O35: Exchange Activity | P35: To be confirmed by Engineering | Q35: Medium
A36: withdrawal_requested | B36: Withdrawal request created | C36: User requested a withdrawal | D36: Required: user_id | E36: Required: event_id (unique) | F36: Required: event_timestamp (UTC) | G36: Withdrawals | H36: To Be Verified | I36: withdrawal_id, requested_amount, requested_unit, method | J36: wallet_transaction_id | K36: withdrawal_id: string; requested_amount: decimal; requested_unit: enum; method: enum; wallet_transaction_id: string | L36: withdrawal_id unique; requested_amount greater than 0; method in approved list | M36: Backend | N36: Start of withdrawal lifecycle | O36: Daily Active Users (DAU); Weekly Active Users (WAU); Monthly Active Users (MAU); Returning Users; Cohort Retention (Day N); Feature Adoption Rate; Withdrawal Requests; Pending Withdrawals; Processing Time; Withdrawal Completion Rate; Pending Queue Age; Withdrawal Volume; Withdrawal Method Distribution; Help-Center Engagement | P36: To be confirmed by Engineering | Q36: Critical
A37: withdrawal_processing | B37: Request enters review or processing | C37: A withdrawal started processing | D37: Required: user_id | E37: Required: event_id (unique) | F37: Required: event_timestamp (UTC) | G37: Withdrawals | H37: To Be Verified | I37: withdrawal_id, method | J37: provider_reference_id | K37: withdrawal_id: string; method: enum; provider_reference_id: string | L37: Follows withdrawal_requested; once per withdrawal | M37: Backend | N37: Processing time and queue | O37: Pending Withdrawals; Pending Queue Age | P37: To be confirmed by Engineering | Q37: High
A38: withdrawal_completed | B38: Payout finished | C38: A withdrawal was paid out | D38: Required: user_id | E38: Required: event_id (unique) | F38: Required: event_timestamp (UTC) | G38: Withdrawals | H38: To Be Verified | I38: withdrawal_id, method, completed_amount, requested_unit, wallet_transaction_id | J38: provider_reference_id | K38: withdrawal_id: string; method: enum; completed_amount: decimal; requested_unit: enum; wallet_transaction_id: string; provider_reference_id: string | L38: Follows withdrawal_processing; one linked debit; completed_amount not above requested unless a fee rule exists | M38: Backend | N38: Payout output | O38: Completed Withdrawals; Pending Withdrawals; Processing Time; Withdrawal Completion Rate; Withdrawal Volume; Withdrawal Method Distribution | P38: To be confirmed by Engineering | Q38: Critical
A39: withdrawal_rejected | B39: Request refused | C39: A withdrawal was rejected | D39: Required: user_id | E39: Required: event_id (unique) | F39: Required: event_timestamp (UTC) | G39: Withdrawals | H39: To Be Verified | I39: withdrawal_id, method, reason_category | K39: withdrawal_id: string; method: enum; reason_category: enum | L39: reason_category required; cannot follow withdrawal_completed | M39: Backend | N39: Understand friction | O39: Pending Withdrawals; Rejected Withdrawals; Processing Time | P39: To be confirmed by Engineering | Q39: High
A40: withdrawal_reversed | B40: Completed payout undone or returned | C40: A completed withdrawal was reversed | D40: Required: user_id | E40: Required: event_id (unique) | F40: Required: event_timestamp (UTC) | G40: Withdrawals | H40: To Be Verified | I40: withdrawal_id, method, reason_category, wallet_transaction_id | J40: provider_reference_id | K40: withdrawal_id: string; method: enum; reason_category: enum; wallet_transaction_id: string; provider_reference_id: string | L40: Must follow withdrawal_completed | M40: Backend | N40: Payout reliability | O40: Reversed Withdrawals | P40: To be confirmed by Engineering | Q40: High
...

Sheet Common_Envelope
A1: Property | B1: Type | C1: Required? | D1: Meaning (applies to every event)
A2: event_id | B2: string | C2: Yes | D2: Unique key for this event occurrence; a retry reuses the same id
A3: event_name | B3: string | C3: Yes | D3: Name from the catalogue, following the naming standard
A4: event_timestamp | B4: timestamp (UTC) | C4: Yes | D4: When the event happened, ISO 8601 UTC
A5: received_timestamp | B5: timestamp (UTC) | C5: Yes (added on receipt) | D5: When the analytics pipeline received it; detects delay and clock problems
A6: user_id | B6: string | C6: Yes | D6: Stable user key; never email, phone or name
A7: schema_version | B7: string | C7: Yes | D7: Version of the event definition, so changes stay traceable
A8: platform | B8: string (enum) | C8: Yes | D8: android, ios or web (list to be agreed)
A9: app_version | B9: string | C9: Yes | D9: Version of the app that emitted the event
A10: source | B10: string (enum) | C10: Yes | D10: frontend, backend or provider
A11: session_id | B11: string | C11: Optional | D11: Present only if session tracking is adopted

Sheet Naming_Standard
A1: Rule | B1: Standard | C1: Example
A2: Pattern | B2: object_action: the thing, then what happened to it, in snake_case | C2: task_completed, reward_credited, user_registered
A3: Tense | B3: Action in the past tense, because an event records something that has already happened | C3: withdrawal_completed, not withdrawal_complete
A4: State-entry exceptions | B4: Two events keep the state word from the brief's minimum list: reward_pending and withdrawal_processing | C4: Documented exceptions, nothing else uses this form
A5: Case and characters | B5: Lowercase letters, digits and underscores only; no spaces, no abbreviations unless standard | C5: wallet_transaction_created
A6: Feature in a property, not the name | B6: Use a generic event with a feature or source_feature property when behaviour is the same across features | C6: reward_credited with source_feature = spin, not spin_reward_credited
A7: Feature-specific objects | B7: Allowed when the object is itself a feature object | C7: spin_started, mission_completed, mining_claimed
A8: Outcome vs interaction | B8: Interactions can come from the frontend (task_opened); outcomes must come from the backend (reward_credited, task_completed) | C8: Prevents counting what the UI showed as what actually happened
A9: Stability | B9: Released event names are not renamed. A change is a new version or a new event, recorded in the change log | C9: See Work Package Q
A10: No personal data | B10: No personal data in event names or properties | C10: See Work Package B excluded data

Sheet Brief_Coverage
A1: Event from brief's minimum list | B1: In catalogue?
A2: user_registered | B2: =IF(COUNTIF(Event_Catalogue!A:A,A2)>0,"Yes","No") -> Yes
A3: user_logged_in | B3: =IF(COUNTIF(Event_Catalogue!A:A,A3)>0,"Yes","No") -> Yes
A4: user_logged_out | B4: =IF(COUNTIF(Event_Catalogue!A:A,A4)>0,"Yes","No") -> Yes
A5: onboarding_started | B5: =IF(COUNTIF(Event_Catalogue!A:A,A5)>0,"Yes","No") -> Yes
A6: onboarding_completed | B6: =IF(COUNTIF(Event_Catalogue!A:A,A6)>0,"Yes","No") -> Yes
A7: task_viewed | B7: =IF(COUNTIF(Event_Catalogue!A:A,A7)>0,"Yes","No") -> Yes
A8: task_opened | B8: =IF(COUNTIF(Event_Catalogue!A:A,A8)>0,"Yes","No") -> Yes
A9: task_started | B9: =IF(COUNTIF(Event_Catalogue!A:A,A9)>0,"Yes","No") -> Yes
A10: task_completed | B10: =IF(COUNTIF(Event_Catalogue!A:A,A10)>0,"Yes","No") -> Yes
A11: task_failed | B11: =IF(COUNTIF(Event_Catalogue!A:A,A11)>0,"Yes","No") -> Yes
A12: reward_credited | B12: =IF(COUNTIF(Event_Catalogue!A:A,A12)>0,"Yes","No") -> Yes
A13: reward_pending | B13: =IF(COUNTIF(Event_Catalogue!A:A,A13)>0,"Yes","No") -> Yes
... A33: withdrawal_reversed | B33: =IF(COUNTIF(Event_Catalogue!A:A,A33)>0,"Yes","No") -> Yes
